[2024-12-17T01:38:35.825+0000] {taskinstance.py:1157} INFO - Dependencies all met for dep_context=non-requeueable deps ti=<TaskInstance: tuyensinh_pipeline.process_notifications manual__2024-12-17T01:38:31.929313+00:00 [queued]>
[2024-12-17T01:38:35.832+0000] {taskinstance.py:1157} INFO - Dependencies all met for dep_context=requeueable deps ti=<TaskInstance: tuyensinh_pipeline.process_notifications manual__2024-12-17T01:38:31.929313+00:00 [queued]>
[2024-12-17T01:38:35.833+0000] {taskinstance.py:1359} INFO - Starting attempt 1 of 1
[2024-12-17T01:38:35.847+0000] {taskinstance.py:1380} INFO - Executing <Task(PythonOperator): process_notifications> on 2024-12-17 01:38:31.929313+00:00
[2024-12-17T01:38:35.851+0000] {standard_task_runner.py:57} INFO - Started process 79 to run task
[2024-12-17T01:38:35.854+0000] {standard_task_runner.py:84} INFO - Running: ['airflow', 'tasks', 'run', 'tuyensinh_pipeline', 'process_notifications', 'manual__2024-12-17T01:38:31.929313+00:00', '--job-id', '35', '--raw', '--subdir', 'DAGS_FOLDER/tuyensinh_dag.py', '--cfg-path', '/tmp/tmphko6o_ii']
[2024-12-17T01:38:35.856+0000] {standard_task_runner.py:85} INFO - Job 35: Subtask process_notifications
[2024-12-17T01:38:35.901+0000] {task_command.py:415} INFO - Running <TaskInstance: tuyensinh_pipeline.process_notifications manual__2024-12-17T01:38:31.929313+00:00 [running]> on host a3dab00b56e7
[2024-12-17T01:38:35.973+0000] {taskinstance.py:1660} INFO - Exporting env vars: AIRFLOW_CTX_DAG_OWNER='NghiaLT' AIRFLOW_CTX_DAG_ID='tuyensinh_pipeline' AIRFLOW_CTX_TASK_ID='process_notifications' AIRFLOW_CTX_EXECUTION_DATE='2024-12-17T01:38:31.929313+00:00' AIRFLOW_CTX_TRY_NUMBER='1' AIRFLOW_CTX_DAG_RUN_ID='manual__2024-12-17T01:38:31.929313+00:00'
[2024-12-17T01:38:35.974+0000] {notification_pipeline.py:358} INFO - Starting process notifications task.
[2024-12-17T01:38:36.491+0000] {notification_pipeline.py:366} ERROR - Error in process_notifications_task: [Errno 21] Is a directory: '/opt/airflow/data/notification_data/'
[2024-12-17T01:38:36.492+0000] {taskinstance.py:1935} ERROR - Task failed with exception
Traceback (most recent call last):
  File "/home/airflow/.local/lib/python3.9/site-packages/airflow/operators/python.py", line 192, in execute
    return_value = self.execute_callable()
  File "/home/airflow/.local/lib/python3.9/site-packages/airflow/operators/python.py", line 209, in execute_callable
    return self.python_callable(*self.op_args, **self.op_kwargs)
  File "/opt/airflow/pipelines/notification_pipeline.py", line 362, in process_notifications_task
    preprocessor.save_to_json()
  File "/opt/airflow/pipelines/notification_pipeline.py", line 309, in save_to_json
    with open(self.output_file, 'w', encoding='utf-8') as f:
IsADirectoryError: [Errno 21] Is a directory: '/opt/airflow/data/notification_data/'
[2024-12-17T01:38:36.501+0000] {taskinstance.py:1398} INFO - Marking task as FAILED. dag_id=tuyensinh_pipeline, task_id=process_notifications, execution_date=20241217T013831, start_date=20241217T013835, end_date=20241217T013836
[2024-12-17T01:38:36.513+0000] {standard_task_runner.py:104} ERROR - Failed to execute job 35 for task process_notifications ([Errno 21] Is a directory: '/opt/airflow/data/notification_data/'; 79)
[2024-12-17T01:38:36.547+0000] {local_task_job_runner.py:228} INFO - Task exited with return code 1
[2024-12-17T01:38:36.562+0000] {taskinstance.py:2776} INFO - 0 downstream tasks scheduled from follow-on schedule check
